Workbook

Sheet README
A1: Project A open-items LEDGER
A2: Written for | B2: You (the student, thesis owner). This is the single canonical place for the current state of Project A's open items. Date 2026-10-19; repository HEAD d791135.
A3: Status of this file | B3: Tracked working document (record class SUM, unverified) at design/ledger/, committed locally under AUTH-016; a read-only CSV export of the Ledger, Archive, Questions, Links, Aliases and Change log sits in design/ledger/export/ (derived; this workbook stays canonical). The human pushes; nothing is pushed by the lead. Contents: 258 unique rows (174 in Ledger, 84 already closed in Archive), 52 questions, 173 question-to-item links. Categories, clusters, order and dependencies are MY JUDGEMENT [I]; every status has a basis column. Work on it is covered by AUTH-016 (evidence only; see ops/AUTHORIZATIONS.md).
A4: USE THESE THREE TABS | B4: 1) Questions: type your answers in the yellow cells (column K). 2) Ledger: filter by Active? = Yes, sort by Order; rows flagged REVISE have a new answer waiting for me. 3) Overview: counts and integrity checks (all checks must be 0).
A5: How answering works | B5: You type an answer in Questions (column K), optionally pick Answer type, date and provenance (was it verbatim? from which message or file?). The Links sheet connects each question to the ledger items it CLOSES / NARROWS / INFORMS. Ledger columns 'Unanswered linked questions' and 'Review flag' update by formula, so the rows that need revising light up. You do not edit statuses yourself.
A6: How I revise (next session) | B6: For each answered question I (1) re-read the linked ledger rows, (2) set their Current status, Status date, Status basis, Decision/result, (3) append one row per change to the Change log, (4) mark the question REVIEWED with 'Resulting ledger changes', (5) move rows whose status is CLOSED to the Archive (delete from Ledger, same columns), and (6) add any new items the answer opens, with the next free ID. Partly answered rows stay in the Ledger with status PARTLY ANSWERED and a sharper description of the remainder.
A7: No-duplicates rules | B7: One row per item, ever. A LedgerID is never reused or renumbered; a merged item keeps its ID with status SUPERSEDED / MERGED and a pointer. Other names (SRC-06/07 OI rows, CH-, HYP-, REQ-, REGISTER Q) live in the Aliases sheet, not as extra rows. Before adding a row, search Aliases and Ledger titles. Overview checks count duplicate IDs, duplicate titles, IDs in both Ledger and Archive, orphan links and duplicate aliases.
A8: Statuses | B8: OPEN; PARTLY ANSWERED (a named clause is answered; the remainder is stated); UNRUN (a test with no result); NOT LOCATED (bounded search found nothing; not 'does not exist'); LIMITATION - ACCEPTANCE PENDING; DEFERRED (parked with a reopen trigger); ANSWER RECEIVED - TO REVISE; CLOSED - BY EVIDENCE; CLOSED - BY DECISION (needs the decision-maker's own words and date); CLOSED - CLAUSE (a narrow clause closed within its cited record); ACCEPTED LIMITATION (you accepted it); SUPERSEDED / MERGED; WITHDRAWN. Active? = Yes for open-type statuses, Parked for DEFERRED, No for closed-type.
A9: Repo-answerable? | B9: Answered (see basis): the repo already answers it. Yes - stored text, unread: the source text is stored in evidence/sources.json but nobody has read the decisive passage in this workspace, so closing it is a cheap local read via tools/origin_extract.py. Partly: some parts stored or read. No: not in the repo. n/a: a decision or a test.
A10: Closes by / Gate / Cluster | B10: Closes by = what kind of action closes the item (decision by Joaa, decision by you, record fix, desk analysis, source re-read, directed literature search, author/vendor, pilot test, confirmatory study, accept as limitation, time recheck, cross-reference). Gate = the earliest stage it must precede (G1 before ANY implementation ... G5 housekeeping). Cluster = items that one answer or one test moves together.
A11: Other tabs | B11: Archive (closed rows) | Change log (append-only history) | Links | Supervisor statements (Joaa's 19 Oct messages, verbatim) | Aliases | Steps (25-step order in 6 waves) | Clusters | Decision effects (what each possible answer changes) | Gates (what must be solved before implementation) | Dependencies (HARD/SOFT edges) | Sources (coverage register: what was and was not read) | External evidence (INT-01/02 claims relayed by SRC-12, unverified) | Rules (carried from SRC-11/12) | Lists (vocabularies for the dropdowns).
A12: Coverage | B12: See Sources. Everything in SRC-11 and SRC-12 is represented (55 canonical items, 64 sub-rows, 8 answered clauses, Phase 0-2 items, evidence table, rules). The repo sweep covered REGISTER, COMPARISON, CAVEATS, SAFEGUARDS, STATE, AUTH, all 14 hypotheses, all 74 challenge records (front matter; 24 open ones read), v4 in full, v2-05/06, v3-04 and parts of v1-v3. Areas NOT read are listed in Sources; append rows if a later sweep finds more.
A13: Honest limits | B13: Formulas could not be pre-computed here (no spreadsheet engine installed); Excel/LibreOffice/Google Sheets compute them on open, and some previewers show blanks. 'Order', 'Wave', 'Unlocks' and Dependencies categories are derived at build time and do not update if you edit prerequisites; counts, flags and integrity checks are live.
... A16: Where it lives; how it changes | B16: design/ledger/PROJECT_A_OPEN_ITEMS_LEDGER.xlsx is the single canonical copy. Edit it in place and never rebuild it from scripts (a rebuild would overwrite typed answers). Each batch of closures is one local commit that includes the workbook and the regenerated CSV export (design/ledger/export_ledger.py). Evidence rule (AUTH-016): repo evidence first; if the repo has none, public web searches and fetches for that item, stored with URL, time and SHA-256. Closing a decision needs the decision-maker's own words and date.

Sheet Questions
A1: QID | B1: Asked of | C1: Question (neutral wording; one issue each) | D1: Answer format / options | E1: Why it matters | F1: Also known as | G1: Ask at step | H1: Ledger items it CLOSES / NARROWS (snapshot; see Links) | I1: Items it only INFORMS (snapshot) | J1: Ledger items open because of it (formula) | K1: YOUR ANSWER (type here) | L1: Answer type | M1: Answer date | N1: Review status | O1: Provenance (verbatim? where from) | P1: Revised on / by | Q1: Resulting ledger changes
A2: Q-J01 | B2: Joaa | C2: Does the June 2026 expose still govern the thesis scope? If anything changed, which exact clauses are amended (compact interfaces L0-L3, execute/expand/abstain, lifecycle/removal, staged policy, evaluation)? | D2: Governs unchanged | Amended in these clauses: ... | Replaced by the October staged-policy framing | Other | E2: Decides which parts of Project A every test and design choice must cover; the repo cannot see the June text. | F2: SRC-12 1B 'Governing scope'; REGISTER G.3 Q1 (part) | G2: S05 | H2: C-D01 (closes), C-D07 (narrows) | I2: C-D03, C-D06, C-D08, N-13 | J2: =COUNTIFS(Links!$A$2:$A$600,A2,Links!$C$2:$C$600,"<>INFORMS") | K2: [Answered by the human] line 6: the expose does not govern; its ideas are candidates verified like any other. | L2: You decided | M2: 2026-10-21 | N2: REVIEWED | O2: INT-T-005 (requirements/intake/2026-10-21-user-decisions-after-meetings.md) | P2: 2026-10-21 / Claude | Q2: see the Change log of 2026-10-21
A3: Q-J02 | B3: Joaa | C3: Is the research question's unit 'count of tools' (your 14 Oct wording) or model-visible tokens / cost, and does 'we don't need to change it' keep the 'count of tools' wording? | D3: Count of tools | Tokens | Cost | Combination: ... | Other | E3: Changes the criterion and which surface is chosen; with thousands of tools the count cannot decide feasibility (tokens do). | F3: REGISTER G.3 Q1; v4-01 Q3 (first part) | G3: S06 | H3: C-D02 (narrows) | I3: N-1, N-13 | J3: =COUNTIFS(Links!$A$2:$A$600,A3,Links!$C$2:$C$600,"<>INFORMS") | K3: [Answered] 'your idea was never to filter out tools. your idea was to save tokens ... The problem was to save token' (INT-T-004 E524-E526); RQ wording kept with 'count of tools' (INT-T-003 L159); 'narrowing down from 100 to 10 ... reducing 90% of token' (L377). | L3: Joaa said | M3: 2026-10-02 / 10-14 / 10-21 (meetings) | N3: REVIEWED | O3: Transcript lines in INT-T-002/003/004 (AUTH-018); mapping checked by FND-0035, FND-0036 | P3: 2026-10-21 / Claude | Q3: see the Change log of 2026-10-21
A4: Q-J03 | B4: Joaa | C4: What should be primarily minimised or reported: model-visible input tokens, the billed cost (input, cache write, cache read and output tokens under a named price table), or a stated combination? Should output tokens count? | D4: Tokens | Bill | Both with priority ... | Other; Output tokens: count / report only / ignore | E4: Replaces the AUTH-006 working objective if it changes; fixes what pilots report as primary (they can record everything either way). | F4: WhatsApp 19 Oct; STATE pending (a); SRC-12 1B 'Research objective' | G4: S06 | H4: C-D02 (closes), N-1 (closes), N-4 (closes), C-D08/EC5 (narrows) | I4: N-10, C-D08/TOK, C-E05, C-S20 | J4: =COUNTIFS(Links!$A$2:$A$600,A4,Links!$C$2:$C$600,"<>INFORMS") | K4: [Answered by the human] line 8 and line 16: minimise the bill on average over turns and sessions, accuracy nearly the same; canonical equation of components. | Earlier from the meetings: [Partly] Money cost per turn, tokens and response time averaged over turns (INT-T-002 L275, L302, L354); 'we will not drop the cost' (INT-T-004 E697). No single primary estimand or price table named. | L4: You decided | M4: 2026-10-21 | N4: REVIEWED | O4: INT-T-005 (requirements/intake/2026-10-21-user-decisions-after-meetings.md) | P4: 2026-10-21 / Claude | Q4: see the Change log of 2026-10-21
A5: Q-J04 | B5: Joaa | C5: Over what horizon should cost be measured: one run, several turns within a conversation, or across sessions? Is cache expiry between sessions in scope? | D5: One run | Several turns | Across sessions (with session gap assumptions ...) | Cache expiry in/out of scope | E5: Across sessions adds session count and gap as regime variables and needs a session vehicle. | F5: WhatsApp 19 Oct; STATE pending (a) | G5: S06 | H5: N-3 (closes), C-D02 (narrows), C-D08/EC1 (narrows) | I5: C-S04, N-12 | J5: =COUNTIFS(Links!$A$2:$A$600,A5,Links!$C$2:$C$600,"<>INFORMS") | K5: [Answered] Average over many turns, a few failing turns may cost more (INT-T-002 L306-L320); a return 'tomorrow' should start from a short summary (L369-L384); 'save token for a number of turns' (INT-T-004 E778). | L5: Joaa said | M5: 2026-10-02 / 10-14 / 10-21 (meetings) | N5: REVIEWED | O5: Transcript lines in INT-T-002/003/004 (AUTH-018); mapping checked by FND-0035, FND-0036 | P5: 2026-10-21 / Claude | Q5: see the Change log of 2026-10-21
A6: Q-J05 | B6: Joaa | C6: Memory scope: only our stored record of tools previously found and used (per user or role, so a returning user starts with those tools), or also storage/summarisation of conversation history, or full agent memory? | D6: Tool-usage memory only | Plus conversation memory | Full agent memory | Other | E6: Decides whether cross-session discovery memory (N-6, N-7) is in the thesis, deferred, or enlarged. | F6: STATE pending (b); WhatsApp 19 Oct | G6: S06 | H6: N-2 (closes), N-6 (narrows), N-7 (narrows), C-D07 (narrows), N-22 (narrows) | I6: N-3 | J6: =COUNTIFS(Links!$A$2:$A$600,A6,Links!$C$2:$C$600,"<>INFORMS") | K6: [Answered] 'it depends on what you are building' (INT-T-002 L146); 'you can do only memory and tool calls. Forget about knowledge ... memory should help tool calls' (L223-L225); summary of interaction and tool calls, relevant part first (L245, L375-L384); 'tools and memory' (L390). | L6: Joaa said | M6: 2026-10-02 / 10-14 / 10-21 (meetings) | N6: REVIEWED | O6: Transcript lines in INT-T-002/003/004 (AUTH-018); mapping checked by FND-0035, FND-0036 | P6: 2026-10-21 / Claude | Q6: see the Change log of 2026-10-21
A7: Q-J06 | B7: Joaa | C7: Joaa wrote: 'So you have to combine all three to find the best policy: MCP server context, memory, explicit caching.' How should the combination be treated in this thesis: all three as the design space, a subset, or later work? | D7: All three | A subset: ... | Later work | Other | E7: The combination has not been evaluated in the repo's sources yet; whether it is the design space is a scope choice, and the proposal can be adopted, refined or narrowed. | F7: Joaa 19 Oct 12:22 (S-J-004) | G7: S06 | H7: N-22 (closes), C-D07 (narrows), C-D08/ARMS-CACHE (narrows) | I7: N-2 | J7: =COUNTIFS(Links!$A$2:$A$600,A7,Links!$C$2:$C$600,"<>INFORMS") | K7: [Partly] Explicit cache 'applicable for memory ... knowledge' (INT-T-002 L197) in the 'all in theory' part (L221); practical scope tools and memory only (L223-L225). | L7: Joaa said | M7: 2026-10-02 / 10-14 / 10-21 (meetings) | N7: NEEDS FOLLOW-UP | O7: Transcript lines in INT-T-002/003/004 (AUTH-018); mapping checked by FND-0035, FND-0036 | P7: 2026-10-21 / Claude | Q7: see the Change log of 2026-10-21
A8: Q-J07 | B8: Joaa | C8: Must each stage (step) save tokens, or is it enough that the whole trajectory/policy does? Does the possibility of re-adding a tool change your answer? | D8: Per stage | Per trajectory | Per policy over many requests | Other | E8: Decides how 'a stage pays' is tested and whether insurance/recovery stages are allowed. | F8: REGISTER G.3 Q4; SRC-12 1B | G8: S07 | H8: C-D04 (closes) | I8: C-D08/ARMS | J8: =COUNTIFS(Links!$A$2:$A$600,A8,Links!$C$2:$C$600,"<>INFORMS") | K8: [Answered] 'each step is there to save some token' (INT-T-004 E774); saving judged over a number of turns, one dearer turn 'doesn't matter' (E778-E790). | L8: Joaa said | M8: 2026-10-02 / 10-14 / 10-21 (meetings) | N8: REVIEWED | O8: Transcript lines in INT-T-002/003/004 (AUTH-018); mapping checked by FND-0035, FND-0036 | P8: 2026-10-21 / Claude | Q8: see the Change log of 2026-10-21
A9: Q-J08 | B9: Joaa | C9: Is the staged 'one question per step' graph a binding form of the policy, or an illustration? Is a policy whose stages appear only where a stated test justifies them (including zero narrowing stages) acceptable? | D9: Binding | Illustration; stages only where justified | Other | E9: If binding, the graph must contain real narrowing stages even if the study finds none pays. | F9: REGISTER G.3 Q2; v4-01 Q1; SRC-12 1B 'Policy form' | G9: S07 | H9: C-D03 (closes) | I9: C-D10, C-S11, C-S11/CASCADE, C-D06 | J9: =COUNTIFS(Links!$A$2:$A$600,A9,Links!$C$2:$C$600,"<>INFORMS") | K9: [Answered by the supervisor's words and the human's decision] Supervisor 14 Oct: staged graph with re-adding (INT-T-003 L386-L404); the human: keep it and combine it with memory-informed tool offering (INT-T-005 line 5). | Earlier: [Partly] 14 Oct: a staged graph with re-adding, 'that is your novelty' (INT-T-003 L386-L404); 21 Oct: scope memory and tool calls, graph not mentioned (INT-T-002 L223-L225). | L9: You decided | M9: 2026-10-21 | N9: REVIEWED | O9: INT-T-005 (requirements/intake/2026-10-21-user-decisions-after-meetings.md); INT-T-002/003/004 | P9: 2026-10-21 / Claude | Q9: see the Change log of 2026-10-21
A10: Q-J09 | B10: Joaa | C10: What do 'context' and 'scenario' mean: the individual request, the trajectory so far, or the deployment? | D10: Request | Trajectory | Deployment | Combination | Other | E10: v4 adapts at deployment level and via the request/trajectory only through optional stages. | F10: v4-01 Q2; REQ-O14-09 | G10: S07 | H10: C-D03/CONTEXT (closes), C-D03 (narrows) | J10: =COUNTIFS(Links!$A$2:$A$600,A10,Links!$C$2:$C$600,"<>INFORMS") | K10: [Partly] 14 Oct: who invokes the agent (INT-T-003 L261); 21 Oct: what the model is given, tools, knowledge, memory, settings, modalities (INT-T-002 L176-L190). | L10: Joaa said | M10: 2026-10-02 / 10-14 / 10-21 (meetings) | N10: NEEDS FOLLOW-UP | O10: Transcript lines in INT-T-002/003/004 (AUTH-018); mapping checked by FND-0035, FND-0036 | P10: 2026-10-21 / Claude | Q10: see the Change log of 2026-10-21
A11: Q-J10 | B11: Joaa | C11: What does 'which one applies at which stage' mean: what are the 'stages' (policy stages or evaluation stages) and what is 'which one'? What does 'time' mean in 'which one works at which time'? | D11: Free text | E11: Undefined antecedents in the excerpts E4 and E6. | F11: REQ-O14-11; REQ-O14-06 | G11: S07 | H11: C-D03/STAGES (closes) | J11: =COUNTIFS(Links!$A$2:$A$600,A11,Links!$C$2:$C$600,"<>INFORMS") | K11: [Answered] 'which one applies at which stage. You will have different stages' (INT-T-003 L306-L308); 'At each step you have to ask yourself one question' (L390). | L11: Joaa said | M11: 2026-10-02 / 10-14 / 10-21 (meetings) | N11: REVIEWED | O11: Transcript lines in INT-T-002/003/004 (AUTH-018); mapping checked by FND-0035, FND-0036 | P11: 2026-10-21 / Claude | Q11: see the Change log of 2026-10-21
A12: Q-J11 | B12: Joaa | C12: Who or what should answer each stage's question: the model, a rule, or a score? | D12: Model | Rule | Score | Empirical question (test both) | Other | E12: v4 leaves it empirical; a restriction changes the arms. | F12: COMPARISON section 4 | G12: S07 | H12: C-D03/ANSWERER (closes) | I12: C-S11 | J12: =COUNTIFS(Links!$A$2:$A$600,A12,Links!$C$2:$C$600,"<>INFORMS") | K12: [Partly] Stage one from who invokes (INT-T-003 L261); later stage Executor-style or semantic narrowing, 'You have to figure it out' (L306-L308). | L12: Joaa said | M12: 2026-10-02 / 10-14 / 10-21 (meetings) | N12: NEEDS FOLLOW-UP | O12: Transcript lines in INT-T-002/003/004 (AUTH-018); mapping checked by FND-0035, FND-0036 | P12: 2026-10-21 / Claude | Q12: see the Change log of 2026-10-21
A13: Q-J12 | B13: Joaa | C13: Is graded/partial exposure (names only, compact schema, full schema) still a required lens, as in the June L0-L3 and the 2 Oct tier example? | D13: Required | Optional | Dropped | E13: The 14 Oct excerpts describe keep/remove and re-adding, not grades. | F13: COMPARISON C5; REQ-D1 R9 | G13: S05 | H13: C-D07/GRADED (closes), C-D07 (narrows), C-D08/EC3 (narrows) | J13: =COUNTIFS(Links!$A$2:$A$600,A13,Links!$C$2:$C$600,"<>INFORMS") | K13: [Answered by the supervisor's words and the human's decision] Supervisor 2 Oct: one lens, not the best way (INT-T-004 E550-E570); the human: treat such ideas as candidates (INT-T-005 lines 1, 6). | Earlier: [Partly] Partial information as 'this lens', 'not saying this is the best way', numbers 'not rigid' (INT-T-004 E550-E570, E774). | L13: You decided | M13: 2026-10-21 | N13: REVIEWED | O13: INT-T-005 (requirements/intake/2026-10-21-user-decisions-after-meetings.md); INT-T-002/003/004 | P13: 2026-10-21 / Claude | Q13: see the Change log of 2026-10-21
A14: Q-J13 | B14: Joaa | C14: Beyond the point where all tools cannot fit in the context window, is a frontier plus a gap to a pool reference (no noninferiority to expose-all) acceptable? Who sets the margin or token budget from which a policy is chosen? | D14: Acceptable; margin/budget set by ... | Not acceptable; require ... | Other | E14: Without it no claim above n_fit can be made against expose-all. | F14: v4-01 Q4; SRC-12 1B | G14: S08 | H14: C-E06 (closes), C-S13 (narrows), C-S13/CALIB (narrows), C-D08/DELTA (narrows) | I14: C-S13/POOLDIR | J14: =COUNTIFS(Links!$A$2:$A$600,A14,Links!$C$2:$C$600,"<>INFORMS") | K14: [Answered by the human] line 16 (no margin or budget): above the window the frontier is reported. | L14: You decided | M14: 2026-10-21 | N14: REVIEWED | O14: INT-T-005 (requirements/intake/2026-10-21-user-decisions-after-meetings.md) | P14: 2026-10-21 / Claude | Q14: see the Change log of 2026-10-21
A15: Q-J14 | B15: Joaa | C15: Does 'accuracy as high as possible' mean a margin (what size, per stratum?) or a frontier? May the tool count be a reported variable while tokens are the criterion? | D15: Margin of ... | Frontier | Other; Count: reported / criterion | E15: Fixes delta and whether noninferiority testing is used at all. | F15: v4-01 Q3 | G15: S08 | H15: C-D08/DELTA (closes), C-D08/STRATA (narrows), C-D02 (narrows), C-S14 (narrows) | J15: =COUNTIFS(Links!$A$2:$A$600,A15,Links!$C$2:$C$600,"<>INFORMS") | K15: [Answered by the human] line 16: no margin, no budget, no hard thresholds; accuracy nearly the same. | Earlier from the meetings: [Partly] 'match the baseline accuracy while giving lesser and lesser tool' (INT-T-004 E206); 'accuracy as high as possible' (INT-T-003 L159); no margin. | L15: You decided | M15: 2026-10-21 | N15: REVIEWED | O15: INT-T-005 (requirements/intake/2026-10-21-user-decisions-after-meetings.md) | P15: 2026-10-21 / Claude | Q15: see the Change log of 2026-10-21
A16: Q-J15 | B16: Joaa | C16: Would regime-conditional findings (including 'not established' and negative outcomes) count as the findings you require? Is a regime map a sufficient contribution? | D16: Yes | No | Only if ... | Other | E16: Decides whether a null/conditional result is a thesis; also whether a big study is worthwhile. | F16: v4-01 Q5; SRC-12 1B 'Contribution and success' | G16: S08 | H16: C-D06 (closes) | J16: =COUNTIFS(Links!$A$2:$A$600,A16,Links!$C$2:$C$600,"<>INFORMS") | K16: [Answered] 'even if the result is negative it's a thesis ... can you write a paper ... have to do it systematically' (INT-T-003 L363-L365). | L16: Joaa said | M16: 2026-10-02 / 10-14 / 10-21 (meetings) | N16: REVIEWED | O16: Transcript lines in INT-T-002/003/004 (AUTH-018); mapping checked by FND-0035, FND-0036 | P16: 2026-10-21 / Claude | Q16: see the Change log of 2026-10-21
A17: Q-J16 | B17: Joaa | C17: Must the existing code-mediated project ('Executor') be a baseline arm, and which tool or project did you mean by that name? | D17: Required arm | Optional | Not an arm | Identity: ... | E17: The identification of 'Executor' is the researchers', not in the transcript lines. | F17: v4-01 Q6 (first part); CAVEATS 6; A7 | G17: S08 | H17: C-D08/GATEWAY (closes), C-D08/EXEC (narrows), C-D08 (narrows) | I17: AS-07 | J17: =COUNTIFS(Links!$A$2:$A$600,A17,Links!$C$2:$C$600,"<>INFORMS") | K17: [Answered] Executor: 'download this run this ... benchmark it ... This is your baseline. You should have multiple baselines' (INT-T-004 E622-E626); identity: the startup he shared (E583-E612). | L17: Joaa said | M17: 2026-10-02 / 10-14 / 10-21 (meetings) | N17: REVIEWED | O17: Transcript lines in INT-T-002/003/004 (AUTH-018); mapping checked by FND-0035, FND-0036 | P17: 2026-10-21 / Claude | Q17: see the Change log of 2026-10-21
A18: Q-J17 | B18: Joaa | C18: Is writing the evaluation script part of the 21 Oct deliverable, and what does 'implement' cover (script, pilots, experiments)? | D18: Script due | Policy only | Script allowed but no runs | Other | E18: Hard gate before any implementation. | F18: REGISTER G.3 Q5; v4-01 Q6 (second part) | G18: S05 | H18: C-D05 (closes) | I18: C-D09 | J18: =COUNTIFS(Links!$A$2:$A$600,A18,Links!$C$2:$C$600,"<>INFORMS") | K18: [Answered] For 21 Oct: no implementation (INT-T-003 L439); after 21 Oct: experiments with a text-file memory, no engineering, many goals, settings, repeated runs (INT-T-002 L426-L458). | L18: Joaa said | M18: 2026-10-02 / 10-14 / 10-21 (meetings) | N18: REVIEWED | O18: Transcript lines in INT-T-002/003/004 (AUTH-018); mapping checked by FND-0035, FND-0036 | P18: 2026-10-21 / Claude | Q18: see the Change log of 2026-10-21
A19: Q-J18 | B19: Joaa | C19: Does the 21 Oct deliverable replace the 2 Oct one? Was the 2 Oct deliverable (document plus draft step-by-step policy) delivered? | D19: Replaces | Adds to | Other; Delivered: yes/no | E19: Not known to the repo. | F19: REGISTER G.3 Q6; SRC-12 1A-3 | G19: S05 | H19: C-D05 (narrows) | J19: =COUNTIFS(Links!$A$2:$A$600,A19,Links!$C$2:$C$600,"<>INFORMS") | K19: [Answered by the human] line 7: research and a drafted policy now; proof-of-concept tests of parts in a loop; end-to-end later. | Earlier from the meetings: [Partly] 2 Oct: 'write the draft version of uh your policy' (INT-T-004 E804); 14 Oct: 'You need to give me this policy' (INT-T-003 L429-L447). Delivery of the 2 Oct draft not stated. | L19: You decided | M19: 2026-10-21 | N19: REVIEWED | O19: INT-T-005 (requirements/intake/2026-10-21-user-decisions-after-meetings.md) | P19: 2026-10-21 / Claude | Q19: see the Change log of 2026-10-21
A20: Q-J19 | B20: Joaa | C20: Should the offline cost of choosing the configuration (development runs, amortised over a deployment horizon N_dep) be charged to the policy, and over what horizon? | D20: Charged over N = ... | Reported only | Not counted | E20: Part of the accounting contract. | F20: SRC-06 S35 | G20: S08 | H20: C-S17 (closes), C-S20 (narrows) | I20: C-D08/EPS | J20: =COUNTIFS(Links!$A$2:$A$600,A20,Links!$C$2:$C$600,"<>INFORMS") | K20: [Answered by the human] line 10 (see Q-J03): selection and discovery cost is part of the averaged bill. | Earlier from the meetings: [Partly] 'if you use many many more token to filter out the tools then there is no value' (INT-T-004 E230-E232); amortisation not discussed. | L20: You decided | M20: 2026-10-21 | N20: REVIEWED | O20: INT-T-005 (requirements/intake/2026-10-21-user-decisions-after-meetings.md) | P20: 2026-10-21 / Claude | Q20: see the Change log of 2026-10-21
A21: Q-J20 | B21: Joaa | C21: Which numeric parameters do you want fixed now (margin, alpha, strata, epsilon, search width, discovery budget) and which may be set after a pilot? | D21: List: now / after pilot | E21: A parameter can be deferred to a documented pilot only if it cannot change the pilot's interpretation. | F21: SRC-12 Phase 2 | G21: S08 | H21: C-D08 (narrows) | I21: C-D08/ALPHA, C-D08/STRATA, C-D08/EPS, C-D08/KAPPA, C-D08/BS, C-S14, C-D08/CALLLIM, C-D08/EC2, C-D08/EC4, C-D08/EC6, C-D08/HIER, C-D08/RANKER, C-D08/SCOPESTMT | J21: =COUNTIFS(Links!$A$2:$A$600,A21,Links!$C$2:$C$600,"<>INFORMS") | K21: [Answered by the supervisor's words and the human's decision] The human: no margin, budget or threshold (line 16); error control and strata in the end-to-end phase (line 7); kappa, discovery budget and call limit are set while drafting and testing the policy, not by the supervisor. | Earlier: [Partly] Tier sizes 'not rigid' (INT-T-004 E552-E560); start with about 20 samples (E749); delta, epsilon, N_dep not addressed. | L21: You decided | M21: 2026-10-21 | N21: REVIEWED | O21: INT-T-005 (requirements/intake/2026-10-21-user-decisions-after-meetings.md); INT-T-002/003/004 | P21: 2026-10-21 / Claude | Q21: see the Change log of 2026-10-21
A22: Q-J21 | B22: Joaa | C22: How many models or model families should evaluations cover (you said behaviour does not transfer across models)? | D22: N models; families: ... | E22: Drives cost and the sample plan. | F22: REQ-A1 A12 | G22: S08 | H22: AS-12 (narrows), C-D08/EC1 (narrows) | I22: C-D08/CORESWEEP | J22: =COUNTIFS(Links!$A$2:$A$600,A22,Links!$C$2:$C$600,"<>INFORMS") | K22: [Answered by the supervisor's words and the human's decision] The human: models chosen when implementing, several available through a free university API (line 9; REQ-U21-01); the supervisor: repeated runs and several settings (INT-T-002 L441-L443). | Earlier: [Partly] Multiple goals, settings, repeated runs (INT-T-002 L441-L443); number of models not given. | L22: You decided | M22: 2026-10-21 | N22: REVIEWED | O22: INT-T-005 (requirements/intake/2026-10-21-user-decisions-after-meetings.md); INT-T-002/003/004 | P22: 2026-10-21 / Claude | Q22: see the Change log of 2026-10-21
A23: Q-J22 | B23: Joaa | C23: Do you want a prior-art / novelty check of the staged graph (you said 'that is your novelty'), or is novelty not a thesis requirement? | D23: Check required | Not required | Other | E23: v4 makes no novelty claim; every mechanism exists. | F23: REQ-O14-07, -16 | G23: S08 | H23: C-D06/NOVELTY (closes) | J23: =COUNTIFS(Links!$A$2:$A$600,A23,Links!$C$2:$C$600,"<>INFORMS") | K23: [Answered by the supervisor's words and the human's decision] Supervisor: the novelty is the systematic combination and its findings, 'sell it as a novely' (INT-T-003 L227-L233), with a monthly search not to reinvent the wheel (INT-T-004 E591-E605); the human: success is the quality of the work (line 16) and no re-invention (line 1). No separate novelty assessment. | Earlier: [Partly] 'nothing is noble [novel] ... that is actually the novelty. You have to just sell it as a novely' (INT-T-003 L227-L233); monthly search not to reinvent the wheel (INT-T-004 E591-E605). | L23: You decided | M23: 2026-10-21 | N23: REVIEWED | O23: INT-T-005 (requirements/intake/2026-10-21-user-decisions-after-meetings.md); INT-T-002/003/004 | P23: 2026-10-21 / Claude | Q23: see the Change log of 2026-10-21
A24: Q-J23 | B24: Joaa | C24: What did you mean by 'What you have found and narrowed down is some methodologies' (whose findings)? | D24: Free text | E24: Undefined referent in excerpt E1; low priority. | F24: REQ-O14-02 | G24: S05 | H24: C-D01/REFERENT (closes) | J24: =COUNTIFS(Links!$A$2:$A$600,A24,Links!$C$2:$C$600,"<>INFORMS") | K24: [Answered] 'What you have found and narrowed down is some methodologies ... So, we have some mechanism families' (INT-T-003 L159-L161). | L24: Joaa said | M24: 2026-10-02 / 10-14 / 10-21 (meetings) | N24: REVIEWED | O24: Transcript lines in INT-T-002/003/004 (AUTH-018); mapping checked by FND-0035, FND-0036 | P24: 2026-10-21 / Claude | Q24: see the Change log of 2026-10-21
A25: Q-J24 | B25: Joaa | C25: Which providers and models should the bill/cache analysis cover (to choose the price tables)? | D25: Provider/model list | E25: Prices and cache rules are provider-specific. | F25: SRC-12 Phase 2 | G25: S06 | H25: C-D08/EC1 (narrows) | I25: N-5, C-E05, N-1 | J25: =COUNTIFS(Links!$A$2:$A$600,A25,Links!$C$2:$C$600,"<>INFORMS") | K25: [Answered by the human] line 9: chosen when implementing. | L25: You decided | M25: 2026-10-21 | N25: REVIEWED | O25: INT-T-005 (requirements/intake/2026-10-21-user-decisions-after-meetings.md) | P25: 2026-10-21 / Claude | Q25: see the Change log of 2026-10-21
A26: Q-U01 | B26: You | C26: Which dated copy of the June expose did you give Joaa, and what record shows he accepted it (file, email, message, date; or the words and date you recall)? | D26: File/date | Words recalled: ... | None | E26: Your account is not independently recorded. | F26: SRC-12 1A-1 | G26: S01 | H26: C-D01 (narrows) | I26: N-13 | J26: =COUNTIFS(Links!$A$2:$A$600,A26,Links!$C$2:$C$600,"<>INFORMS")
A27: Q-U02 | B27: You | C27: What newer Project A work, results or meeting records exist after 3 October (exact files, logs, dates)? | D27: List of files/dates | None | E27: Avoids duplicate runs; may narrow test items. | F27: SRC-12 1A-2 | G27: S02 | H27: C-D11 (narrows), N-11 (narrows) | J27: =COUNTIFS(Links!$A$2:$A$600,A27,Links!$C$2:$C$600,"<>INFORMS")
A28: Q-U03 | B28: You | C28: May earlier Project A results be reconciled with this workspace, and under which authorization? Or confirm none exist. | D28: Yes, supply and authorize | No | None exist | E28: Reconciliation is out of scope until you authorize it; one answer may narrow many test items. | F28: SRC-12 Phase 0 | G28: S02 | H28: C-D11 (closes), C-P03 (narrows), C-P03/P11 (narrows) | I28: C-S01, C-S02, C-S08, C-S12, C-S13, C-S15, C-S16 | J28: =COUNTIFS(Links!$A$2:$A$600,A28,Links!$C$2:$C$600,"<>INFORMS") | K28: 'also the 27 retreival methods keep it but take care where you use it ... never let it contaminate our work' (human, 2026-10-21, ops/AUTHORIZATIONS.md AUTH-018 section). | L28: You decided | M28: 2026-10-21 | N28: REVIEWED | O28: verbatim, chat 2026-10-21 | P28: 2026-10-21 / Claude | Q28: C-D11 closed by decision; N-11 deferred
A29: Q-U04 | B29: You | C29: What is the status of the Executor 426-slot comparison after 3 October (ran, results, or not run)? | D29: Status/records | Not run | E29: INT-01 shows it had not started at its 3 Oct snapshot. | F29: SRC-12 Phase 0 step 2 | G29: S02 | H29: N-11 (closes) | J29: =COUNTIFS(Links!$A$2:$A$600,A29,Links!$C$2:$C$600,"<>INFORMS")
A30: Q-U05 | B30: You | C30: Was the 2 Oct deliverable provided? What exactly, when, and how (sent file or email)? | D30: Delivered: file/date | Not delivered | E30: REGISTER Q6 cannot be settled without it. | F30: SRC-12 1A-3 | G30: S05 | H30: C-D05 (narrows) | J30: =COUNTIFS(Links!$A$2:$A$600,A30,Links!$C$2:$C$600,"<>INFORMS")
A31: Q-U06 | B31: You | C31: Which decisions do you want Joaa to make, and which are your own operational choices (budget, models, scope)? Keep preferences separate from agreed constraints. | D31: Two lists | E31: Prevents asking Joaa things only you can decide. | F31: SRC-12 1A-4 | G31: S04 | I31: C-D08, C-D09 | J31: =COUNTIFS(Links!$A$2:$A$600,A31,Links!$C$2:$C$600,"<>INFORMS")
A32: Q-U07 | B32: You | C32: What exactly did you send Joaa as 'V3' (files, date), and what was the intermediate presentation? | D32: File names/date | E32: Joaa's 19 Oct feedback is on what he saw; v4 corrections postdate it. | F32: WD-021 | G32: S01 | H32: N-8 (closes) | J32: =COUNTIFS(Links!$A$2:$A$600,A32,Links!$C$2:$C$600,"<>INFORMS")
A33: Q-U08 | B33: You | C33: Paste Joaa's 19 Oct message verbatim, including the 'one tenth' and any 'for an hour' wording. | D33: Paste | E33: The repo holds only a paraphrase. | F33: WhatsApp 19 Oct | G33: S01 | H33: N-9 (closes) | I33: N-5 | J33: =COUNTIFS(Links!$A$2:$A$600,A33,Links!$C$2:$C$600,"<>INFORMS") | K33: Pasted in chat on 2026-10-19; stored verbatim in the 'Supervisor statements' sheet (S-J-001..006), including the '1/10' and 'for an hour' wording. | L33: Document provided | M33: 2026-10-19 | N33: REVIEWED | O33: Forwarded by the student; verbatim copy in the 'Supervisor statements' sheet. | P33: 2026-10-19 / Claude | Q33: N-9 PARTLY ANSWERED (workbook copy; tracked copy pending); N-5 PARTLY ANSWERED; N-22 retitled; new N-25, N-26, N-27; Q-J06 reworded; Q-J25..J27 added
A34: Q-U09 | B34: You | C34: Supply the thesis research question verbatim (who stated it, when), or confirm none is established yet. | D34: Verbatim text | None yet | E34: THESIS_QUESTION.md is a placeholder; E1 is a fragment. | F34: REGISTER G.3 Q3 | G34: S01 | H34: N-13 (closes), C-D01 (narrows) | J34: =COUNTIFS(Links!$A$2:$A$600,A34,Links!$C$2:$C$600,"<>INFORMS")
A35: Q-U10 | B35: You | C35: Confirm or reverse the two-figure presentation (run-time policy vs study protocol), and decide what Joaa is shown. | D35: Confirm | Reverse | Show both | E35: The lead decided it under AUTH-010. | F35: WD-020 | G35: S07 | H35: C-D10 (closes), C-R02 (narrows), C-R02/C10-13 (narrows) | J35: =COUNTIFS(Links!$A$2:$A$600,A35,Links!$C$2:$C$600,"<>INFORMS")
A36: Q-U11 | B36: You | C36: Accept the documented safeguard limits, or authorize fixes; may the stale safeguard text (SAFEGUARDS rows 5 and 17, CLAUDE.md) be updated for your review? | D36: Accept | Fix: ... | Update text | E36: Hard gate before running code here. | F36: STATE open item 7 | G36: S03 | H36: C-D13 (closes), C-D13/HOOKOFF (narrows), C-D13/INTERP (narrows), C-D13/BASHWRITE (narrows), C-D13/INTERACTIVE (narrows), C-D13/PEERS (narrows), C-D13/LEADREG (narrows), C-D13/UNTESTED (narrows), C-D13/WEBTOOLS (narrows), C-D13/TEAMS (narrows), N-19 (narrows) | J36: =COUNTIFS(Links!$A$2:$A$600,A36,Links!$C$2:$C$600,"<>INFORMS") | K36: I accept all 8 in A, (the eight C-D13 limits listed in the lead's table). The second part of this question (whether the stale safeguard text may be updated for your review) is not answered. | L36: You decided | M36: 2026-10-20 | N36: NEEDS FOLLOW-UP | O36: Verbatim, the human's chat message of 2026-10-20 (reply to the lead's list of 17 limitations) | P36: 2026-10-20 / Claude | Q36: 8 limits accepted and archived; C-D13 narrowed; N-19 pinned-text part still waits
A37: Q-U12 | B37: You | C37: Keep or remove design/tool-exposure-policy-proposal.md and EXT-0067..0073 (author unknown)? | D37: Keep | Remove | E37: Provenance of the file is unrecorded. | F37: STATE open item 6 | G37: S03 | H37: N-15 (closes) | J37: =COUNTIFS(Links!$A$2:$A$600,A37,Links!$C$2:$C$600,"<>INFORMS")
A38: Q-U13 | B38: You | C38: Should the Phase 1/2/2b independent results inform the 21 Oct meeting (needs a new AUTH)? | D38: Yes (AUTH) | No | E38: The lead cannot read them. | F38: STATE open item 4 | G38: S02 | H38: N-14 (closes) | I38: C-D12 | J38: =COUNTIFS(Links!$A$2:$A$600,A38,Links!$C$2:$C$600,"<>INFORMS")
A39: Q-U14 | B39: You | C39: Which pilots do you authorize (token composition, billing/cache probe, search initiation, ...), on which provider and model, with what budget cap and whose approval? | D39: List with budgets | None yet | E39: Nothing may run without an AUTH row. | F39: STATE open item 5 | G39: S16 | H39: C-D09 (closes) | J39: =COUNTIFS(Links!$A$2:$A$600,A39,Links!$C$2:$C$600,"<>INFORMS")
A40: Q-U15 | B40: You | C40: Do you want a further independent replication track? | D40: Yes | No | Later | E40: Separate from this audit. | F40: SRC-06 D15 | G40: S25 | H40: C-D12 (closes) | J40: =COUNTIFS(Links!$A$2:$A$600,A40,Links!$C$2:$C$600,"<>INFORMS")
...

Sheet Ledger
A1: LedgerID | B1: Title | C1: Current status | D1: Active? | E1: Review flag | F1: Unanswered linked questions | G1: Closes by (primary) | H1: Cluster | I1: Must precede (gate) | J1: Priority | K1: Order | L1: Wave | M1: Step closes | N1: Owner | O1: Next action | P1: Repo-answerable? | Q1: Kind | R1: Level | S1: Parent ID | T1: What is open (description) | U1: What is known now | V1: Closed when | W1: Hard prerequisites | X1: Soft inputs (may narrow it) | Y1: Linked questions | Z1: Also needs | AA1: Also in cluster(s) | AB1: Reason tags | AC1: Baseline status (SRC-11 / origin) | AD1: Change vs baseline | AE1: Status date | AF1: Status basis (evidence pointer) | AG1: Reopen trigger | AH1: Needs new AUTH? | AI1: Decision / result (on closure) | AJ1: Origin (first source) | AK1: Alias IDs (other names for this item) | AL1: Step first work
A2: N-8 | B2: What exactly did Joaa receive as 'V3'? | C2: OPEN | D2: =IFERROR(INDEX(Lists!$B$2:$B$14,MATCH(C2,Lists!$A$2:$A$14,0)),"?") | E2: =IF(COUNTIFS(Links!$B$2:$B$600,A2,Links!$E$2:$E$600,"Yes")>0,"REVISE","") | F2: =COUNTIFS(Links!$B$2:$B$600,A2,Links!$D$2:$D$600,"No",Links!$C$2:$C$600,"<>INFORMS") | G2: RECORDS-AT-HAND | H2: K1 Scope: what Project A is | I2: G5 Housekeeping / no block | J2: Low | K2: 2 | L2: W0 Orient (no AUTH) | M2: S01 | N2: You | O2: You record what you sent and when | P2: No | Q2: Record fix | R2: Item | T2: What exactly did Joaa receive as 'V3'? The intermediate presentation is not in the repository, and v4 postdates v3. | U2: Unknown from the repo. 2026-10-21 (AUTH-018): the 21 October transcript has the student asking 'Do you like the policy? Um you didn't like it?' (INT-T-002 L135) and no comment on the policy follows; what was sent is still not recorded. | V2: The file(s) you sent and the date are recorded. | Y2: Q-U07 | AC2: n/a (new) | AD2: NEW | AE2: 2026-10-21 | AF2: INT-T-002 (requirements/intake/2026-10-21-supervisor-meeting-2026-10-21-notes-and-transcript.md); mapping design/ledger/notes/MEETINGS-MAPPING-20261021.md checked line by line by FND-0035 and FND-0036; REGISTER section H | AH2: No | AJ2: Review 19 Oct (section 5) | AK2: WD-021 | AL2: S01
A3: N-9 | B3: Joaa's 19 Oct messages: verbatim now stored in this workbook; tracked copy in requirements/ pending | C3: PARTLY ANSWERED | D3: =IFERROR(INDEX(Lists!$B$2:$B$14,MATCH(C3,Lists!$A$2:$A$14,0)),"?") | E3: =IF(COUNTIFS(Links!$B$2:$B$600,A3,Links!$E$2:$E$600,"Yes")>0,"REVISE","") | F3: =COUNTIFS(Links!$B$2:$B$600,A3,Links!$D$2:$D$600,"No",Links!$C$2:$C$600,"<>INFORMS") | G3: RECORDS-AT-HAND | H3: K1 Scope: what Project A is | I3: G5 Housekeeping / no block | J3: Low | K3: 3 | L3: W0 Orient (no AUTH) | M3: S01 | N3: You | O3: Lead drafts the fix; you approve | P3: Partly | Q3: Record fix | R3: Item | T3: The student pasted Joaa's six 19 Oct messages; they are stored verbatim with provenance in the 'Supervisor statements' sheet. Not yet recorded in the repo's requirements/ area with provenance and hash (a tracked change that needs approval). | U3: Verbatim text stored (S-J-001..006). The repo's earlier paraphrase of the caching message ('1/10 of input token for an hour') matches his wording. | V3: Verbatim text recorded in requirements/ with provenance and hash (after your approval), or you decide the workbook copy is enough. | Y3: Q-U08 | AA3: K2 Objective & accounting | AC3: n/a (new) | AD3: NEW | AE3: 2026-10-19 | AF3: Supervisor statements sheet; Questions Q-U08 answer | AH3: No | AJ3: Review 19 Oct (section 5) | AK3: WhatsApp 19 Oct | AL3: S01
A4: C-P03/P11 | B4: First-session reconciliation not executed | C4: OPEN | D4: =IFERROR(INDEX(Lists!$B$2:$B$14,MATCH(C4,Lists!$A$2:$A$14,0)),"?") | E4: =IF(COUNTIFS(Links!$B$2:$B$600,A4,Links!$E$2:$E$600,"Yes")>0,"REVISE","") | F4: =COUNTIFS(Links!$B$2:$B$600,A4,Links!$D$2:$D$600,"No",Links!$C$2:$C$600,"<>INFORMS") | G4: USER-DECISION | H4: K16 Limits & provenance | I4: G5 Housekeeping / no block | J4: Low | K4: 5 | L4: W0 Orient (no AUTH) | M4: S02 | N4: You | O4: You decide (Q-U03) | P4: No | Q4: Record fix | R4: Sub-item | S4: C-P03 | T4: SRC-06 P11: the first-session reconciliation with the origin was not executed. | U4: Out of scope until a separate human authorization. | V4: Repaired or disclosed. | Y4: Q-U03 | AB4: RECORD+DEC | AC4: n/a (sub-item) | AD4: NEW (SRC-11 sub-row) | AE4: 2026-10-19 | AF4: CLAUDE.md; WD-009; CAVEATS row 14 | AH4: Yes (reconciliation) | AJ4: SRC-11 section D5 | AK4: SRC-06 P11, WD-009 | AL4: S02
A5: N-11 | B5: Executor 426-slot comparison: status after 3 October unknown | C5: DEFERRED | D5: =IFERROR(INDEX(Lists!$B$2:$B$14,MATCH(C5,Lists!$A$2:$A$14,0)),"?") | E5: =IF(COUNTIFS(Links!$B$2:$B$600,A5,Links!$E$2:$E$600,"Yes")>0,"REVISE","") | F5: =COUNTIFS(Links!$B$2:$B$600,A5,Links!$D$2:$D$600,"No",Links!$C$2:$C$600,"<>INFORMS") | G5: USER-DECISION | H5: K0 Earlier results | I5: G2 Before the affected pilot/arm | J5: High | K5: 6 | L5: W0 Orient (no AUTH) | M5: S02 | N5: You | O5: none until the trigger fires | P5: No | Q5: Decision | R5: Item | T5: SRC-12 Phase 0 step 2: INT-01 says the Executor 426-slot full comparison had not started at its 3 Oct snapshot; whether it later ran is unknown; the 'quiet-period' date passing does not establish it ran. | U5: Unknown. 2026-10-21 (AUTH-018): deferred: the Executor 426-slot comparison belongs to the earlier work that the human decided to keep outside this work (C-D11). | V5: You supply the later run record or confirm it did not run. | Y5: Q-U02, Q-U04 | Z5: RECORDS-AT-HAND | AB5: ACCESS | AC5: n/a (new) | AD5: NEW (repo sweep) | AE5: 2026-10-21 | AF5: ops/AUTHORIZATIONS.md (AUTH-018) | AG5: The human decides to use the earlier work | AH5: No | AJ5: SRC-12 Phase 0 | AK5: SRC-12 Phase 0 step 2 | AL5: S02
A6: N-14 | B6: Independent Phase 1/2/2b results: should they inform the 21 Oct meeting? | C6: OPEN | D6: =IFERROR(INDEX(Lists!$B$2:$B$14,MATCH(C6,Lists!$A$2:$A$14,0)),"?") | E6: =IF(COUNTIFS(Links!$B$2:$B$600,A6,Links!$E$2:$E$600,"Yes")>0,"REVISE","") | F6: =COUNTIFS(Links!$B$2:$B$600,A6,Links!$D$2:$D$600,"No",Links!$C$2:$C$600,"<>INFORMS") | G6: USER-DECISION | H6: K0 Earlier results | I6: G5 Housekeeping / no block | J6: Low | K6: 7 | L6: W0 Orient (no AUTH) | M6: S02 | N6: You | O6: Answer Q-U13 | P6: No | Q6: Decision | R6: Item | T6: STATE open item 4: the human holds Phase 1 / Phase 2 / Phase 2b results outside the repo; admitting them would need a new AUTH; the lead cannot read them. | U6: Held outside; not read. | V6: Admitted under a new AUTH with labelled provenance, or explicitly kept out. | Y6: Q-U13 | AB6: ACCESS+DEC | AC6: n/a (new) | AD6: NEW (repo sweep) | AE6: 2026-10-19 | AF6: STATE; AUTH-007..009 | AH6: Yes (to admit) | AJ6: repo: STATE open item 4 | AK6: STATE open item 4, AUTH-007..009 | AL6: S02
A7: C-D13 | B7: Workspace safeguards (hooks, deny rules, no sandbox) have known limits; the remote, web tools and fetch hel... | C7: PARTLY ANSWERED | D7: =IFERROR(INDEX(Lists!$B$2:$B$14,MATCH(C7,Lists!$A$2:$A$14,0)),"?") | E7: =IF(COUNTIFS(Links!$B$2:$B$600,A7,Links!$E$2:$E$600,"Yes")>0,"REVISE","") | F7: =COUNTIFS(Links!$B$2:$B$600,A7,Links!$D$2:$D$600,"No",Links!$C$2:$C$600,"<>INFORMS") | G7: USER-DECISION | H7: K16 Limits & provenance | I7: G1 Before any implementation | J7: High | K7: 8 | L7: W0 Orient (no AUTH) | M7: S03 | N7: You | O7: Answer the second part of Q-U11; decide on C-D13/WEBTOOLS | P7: Partly | Q7: Decision | R7: Item | T7: Workspace safeguards (hooks, deny rules, no sandbox) have known limits; the remote, web tools and fetch helper changed the surface; two safeguard texts are stale. | U7: Verifier pass 875 / warn 1 / fail 0 (warn = untracked .workspace). SAFEGUARDS rows 5 and 17 and CLAUDE.md predate AUTH-012/014/015. 2026-10-20: the human accepted eight of the nine documented safeguard limits in their own words ("I accept all 8 in A,"): BASHWRITE, HOOKOFF, INTERACTIVE, INTERP, LEADREG, PEERS, TEAMS, UNTESTED (now in the Archive as ACCEPTED LIMITATION). Open under this item: C-D13/WEBTOOLS and the second part of Q-U11 (whether the stale safeguard text in SAFEGUARDS rows 5 and 17 and CLAUDE.md may be updated for review; the proposal is in design/ledger/notes/N-19-proposed-text-for-pinned-files.md). | V7: Limits accepted or fixed; stale text updated (pinned files need your review). | Y7: Q-U11 | Z7: RECORDS-AT-HAND | AB7: RECORD+DEC | AC7: BOUNDARY - OPEN | AD7: RE-CHARACTERISED | AE7: 2026-10-20 | AF7: Questions Q-U11; chat message of 2026-10-20 | AH7: No | AJ7: SRC-11 canonical | AK7: SRC-06 D16, SRC-06 P12, STATE open item 7 | AL7: S03
A8: C-D13/WEBTOOLS | B8: WebSearch/WebFetch and the fetch helper are now allow-listed; scope rests on the AUTH text only | C8: OPEN | D8: =IFERROR(INDEX(Lists!$B$2:$B$14,MATCH(C8,Lists!$A$2:$A$14,0)),"?") | E8: =IF(COUNTIFS(Links!$B$2:$B$600,A8,Links!$E$2:$E$600,"Yes")>0,"REVISE","") | F8: =COUNTIFS(Links!$B$2:$B$600,A8,Links!$D$2:$D$600,"No",Links!$C$2:$C$600,"<>INFORMS") | G8: USER-DECISION | H8: K16 Limits & provenance | I8: G1 Before any implementation | J8: High | K8: 17 | L8: W0 Orient (no AUTH) | M8: S03 | N8: You | O8: You decide (Q-U11) | P8: Answered (see basis) | Q8: Safeguard limit | R8: Sub-item | S8: C-D13 | T8: AUTH-014 moved WebSearch/WebFetch to allow; AUTH-015 added a pinned fetch helper rule. Scope limits are instructions, not mechanisms. | U8: Documented limit. | V8: Accepted, or fixed (OS sandbox, separate account). | Y8: Q-U11 | Z8: ACCEPT-LIMITATION | AB8: RECORD+DEC | AC8: n/a (sub-item) | AD8: NEW (repo sweep) | AE8: 2026-10-19 | AF8: AUTH-014, AUTH-015; commits bde0cdd, d791135 | AH8: No | AJ8: repo: AUTHORIZATIONS | AL8: S03
A9: C-P03/P12 | B9: Safeguards untested | C9: PARTLY ANSWERED | D9: =IFERROR(INDEX(Lists!$B$2:$B$14,MATCH(C9,Lists!$A$2:$A$14,0)),"?") | E9: =IF(COUNTIFS(Links!$B$2:$B$600,A9,Links!$E$2:$E$600,"Yes")>0,"REVISE","") | F9: =COUNTIFS(Links!$B$2:$B$600,A9,Links!$D$2:$D$600,"No",Links!$C$2:$C$600,"<>INFORMS") | G9: USER-DECISION | H9: K16 Limits & provenance | I9: G5 Housekeeping / no block | J9: Low | K9: 18 | L9: W0 Orient (no AUTH) | M9: S03 | N9: You | O9: You decide | P9: Partly | Q9: Record fix | R9: Sub-item | S9: C-P03 | T9: SRC-06 P12: safeguards were untested. | U9: Deterministic tests exist; interactive/VS Code and adversarial behaviour are untested (see C-D13 children). | V9: Repaired or disclosed. | AB9: RECORD+DEC | AC9: n/a (sub-item) | AD9: NEW (SRC-11 sub-row) | AE9: 2026-10-19 | AF9: ops/SAFEGUARDS.md test index (A1..C8, guard_cases.py 57 cases, R2); known bypasses list | AH9: Yes (reconciliation) | AJ9: SRC-11 section D5 | AK9: SRC-06 P12 | AL9: S03
A10: N-15 | B10: Untracked 19 Oct draft and EXT-0067..0073: keep or remove (author unknown) | C10: OPEN | D10: =IFERROR(INDEX(Lists!$B$2:$B$14,MATCH(C10,Lists!$A$2:$A$14,0)),"?") | E10: =IF(COUNTIFS(Links!$B$2:$B$600,A10,Links!$E$2:$E$600,"Yes")>0,"REVISE","") | F10: =COUNTIFS(Links!$B$2:$B$600,A10,Links!$D$2:$D$600,"No",Links!$C$2:$C$600,"<>INFORMS") | G10: USER-DECISION | H10: K16 Limits & provenance | I10: G5 Housekeeping / no block | J10: Low | K10: 19 | L10: W0 Orient (no AUTH) | M10: S03 | N10: You | O10: Answer Q-U12 | P10: n/a | Q10: Decision | R10: Item | T10: design/tool-exposure-policy-proposal.md and EXT-0067..0073 were committed with a provenance banner; author and authorization unrecorded. | U10: Not adopted as a record; flagged. | V10: Kept (with provenance) or removed. | Y10: Q-U12 | AB10: RECORD+DEC | AC10: n/a (new) | AD10: NEW (repo sweep) | AE10: 2026-10-19 | AF10: v4-03 section 4 | AH10: No | AJ10: repo: STATE open item 6; v4-03 section 4 | AK10: STATE open item 6 | AL10: S03
A11: N-13 | B11: Thesis question not supplied | C11: OPEN | D11: =IFERROR(INDEX(Lists!$B$2:$B$14,MATCH(C11,Lists!$A$2:$A$14,0)),"?") | E11: =IF(COUNTIFS(Links!$B$2:$B$600,A11,Links!$E$2:$E$600,"Yes")>0,"REVISE","") | F11: =COUNTIFS(Links!$B$2:$B$600,A11,Links!$D$2:$D$600,"No",Links!$C$2:$C$600,"<>INFORMS") | G11: USER-DECISION | H11: K1 Scope: what Project A is | I11: G3 Before confirmatory study | J11: Normal | K11: 22 | L11: W1 Decide | M11: S05 | N11: You (verbatim text, who, when), Joaa if wording is contested | O11: Answer Q-U09 | P11: No | Q11: Decision | R11: Item | T11: requirements/THESIS_QUESTION.md is a placeholder (status awaiting-user); excerpt E1 is a mid-sentence fragment and was not entered; Q3 asks whether and in what exact wording E1 may be entered. | U11: Not supplied. | V11: The question is entered verbatim with provenance and hash. | Y11: Q-J01, Q-J02, Q-U01, Q-U09 | Z11: JOAA-DECISION | AB11: DEC+ACCESS | AC11: n/a (new) | AD11: NEW (repo sweep) | AE11: 2026-10-19 | AF11: THESIS_QUESTION.md; CAVEATS 17 | AH11: No | AJ11: repo: STATE; REGISTER F and G.3 Q3 | AK11: REGISTER G.3 Q3, CAVEATS 17, STATE open item 3 | AL11: S01
A12: N-26 | B12: Caching mechanisms as policy variables: implicit, explicit (breakpoints, retention) or recorded only? | C12: PARTLY ANSWERED | D12: =IFERROR(INDEX(Lists!$B$2:$B$14,MATCH(C12,Lists!$A$2:$A$14,0)),"?") | E12: =IF(COUNTIFS(Links!$B$2:$B$600,A12,Links!$E$2:$E$600,"Yes")>0,"REVISE","") | F12: =COUNTIFS(Links!$B$2:$B$600,A12,Links!$D$2:$D$600,"No",Links!$C$2:$C$600,"<>INFORMS") | G12: JOAA-DECISION | H12: K9 Cache & billing | I12: G2 Before the affected pilot/arm | J12: High | K12: 33 | L12: W1 Decide | M12: S06 | N12: Joaa | O12: Candidate for the first proof-of-concept | P12: Partly | Q12: Decision | R12: Item | T12: Joaa wrote that vendors 'provide implicit and explicit caching mechanisms so this should also be included in your policy' (S-J-001). Which caching choices are design variables of the policy (explicit breakpoints, cache layout, retention period) and which are provider behaviour that is only recorded? Treated as his proposal, to be adopted, refined or narrowed. | U12: Documented mechanisms in the pages read (facts, not the decision): Anthropic automatic or explicit via cache_control (EXT-0115); Bedrock explicit checkpoints (EXT-0137); Gemini implicit caching on by default, and the Interactions API supports implicit only (EXT-0141); OpenAI GPT-5.6 and later: prompt_cache_options.mode with explicit breakpoints (up to four writes per request) and ttl (EXT-0142); OpenAI earlier models implicit only with prompt_cache_retention (EXT-0142); MCP: server-set ttlMs and cacheScope hints for client-side caching, not a provider prompt cache (EXT-0143). Which of these are variables of the policy is Joaa's decision (Q-J26). Recheck 2026-10-19: the Gemini pricing page now lists Gemini 4 Argon as 'Implicit caching only (explicit caching is not supported)', so explicit-caching availability varies by model within one provider (price-gemini-20261019). 2026-10-21 (AUTH-018): his statement that added information can stay in the explicit cache for the whole conversation at 'negligible cost' (INT-T-002 L207-L209) is in the 'in theory' part (L221); it is recorded as an assertion to test (AS-15). 2026-10-21 (AUTH-019, the human's decisions): the human notes that prompt caching 'may use this as conversation memory in the begining' (line 8): caching as an early, simple memory is a candidate design element. | V12: Variables and recorded-only items listed in the evaluation contract. | X12: C-S03, N-5, C-D02 | Y12: Q-J26 | Z12: DESK-ANALYSIS | AA12: K2 Objective & accounting | AB12: DEC | AC12: n/a (new) | AD12: NEW | AE12: 2026-10-21 | AF12: INT-T-005 (requirements/intake/2026-10-21-user-decisions-after-meetings.md) | AH12: No | AJ12: Joaa 19 Oct (Supervisor statements sheet) | AK12: Joaa 19 Oct 12:15 (implicit and explicit caching), Joaa 19 Oct 12:15 (implicit and explicit caching) | AL12: S06
A13: N-22 | B13: Joaa's proposal: combine MCP server context, memory and explicit caching to find the best policy | C13: PARTLY ANSWERED | D13: =IFERROR(INDEX(Lists!$B$2:$B$14,MATCH(C13,Lists!$A$2:$A$14,0)),"?") | E13: =IF(COUNTIFS(Links!$B$2:$B$600,A13,Links!$E$2:$E$600,"Yes")>0,"REVISE","") | F13: =COUNTIFS(Links!$B$2:$B$600,A13,Links!$D$2:$D$600,"No",Links!$C$2:$C$600,"<>INFORMS") | G13: JOAA-DECISION | H13: K4 Memory & sessions | I13: G2 Before the affected pilot/arm | J13: High | K13: 35 | L13: W1 Decide | M13: S06 | N13: Joaa | O13: N-28 and AS-15 | P13: Partly | Q13: Decision | R13: Sub-item | S13: C-D07 | T13: Joaa wrote: 'So you have to combine all three to find the best policy: 1. MCP server context 2. Memory 3. Explicit caching' (S-J-004). Treated as his proposal for the policy's design space. The repo's sources have not evaluated the three together yet; whether the design space is all three, a subset, or later work is his scope choice, and the proposal may be adopted, refined or narrowed. | U13: Each of the three has separate evidence in the repo; their combination has not been tested. 2026-10-21 (AUTH-018): explicit caching 'is also applicable for memory ... for knowledge' (INT-T-002 L197), said in the part he calls 'all in theory' (L221); 'back to practical' he keeps memory and tool calls only (L223-L225) and does not return to caching. The combination is narrowed to tools and memory; whether explicit caching is part of the practical scope is not said. | V13: In or out of scope; if in, an arm set is defined. | W13: N-9 | Y13: Q-J05, Q-J06 | Z13: TEST-PILOT | AB13: DEC+DATA | AC13: n/a (new) | AD13: NEW (repo sweep) | AE13: 2026-10-21 | AF13: INT-T-002 (requirements/intake/2026-10-21-supervisor-meeting-2026-10-21-notes-and-transcript.md); mapping design/ledger/notes/MEETINGS-MAPPING-20261021.md checked line by line by FND-0035 and FND-0036; REGISTER section H | AH13: No | AJ13: review 19 Oct section 3.2 | AK13: Joaa 19 Oct 12:22 (combine all three) | AL13: S06
A14: C-D03/ANSWERER | B14: Who or what answers each stage's question (model, rule, score)? | C14: PARTLY ANSWERED | D14: =IFERROR(INDEX(Lists!$B$2:$B$14,MATCH(C14,Lists!$A$2:$A$14,0)),"?") | E14: =IF(COUNTIFS(Links!$B$2:$B$600,A14,Links!$E$2:$E$600,"Yes")>0,"REVISE","") | F14: =COUNTIFS(Links!$B$2:$B$600,A14,Links!$D$2:$D$600,"No",Links!$C$2:$C$600,"<>INFORMS") | G14: JOAA-DECISION | H14: K3 Policy form | I14: G2 Before the affected pilot/arm | J14: High | K14: 36 | L14: W1 Decide | M14: S07 | N14: Joaa | O14: Decided by evaluation (pilot design) | P14: No | Q14: Decision | R14: Sub-item | S14: C-D03 | T14: The excerpt does not say; v4 treats system-vs-model as an empirical question. | U14: v4 leaves it empirical. 2026-10-21 (AUTH-018): stage one is decided from context, who invokes the agent (INT-T-003 L261); for a later stage he names Executor-style capability listing or semantic narrowing, 'which one is better ... You have to figure it out' (L306-L308). | V14: Joaa's answer recorded in his words. | Y14: Q-J11 | AB14: DEC | AC14: n/a (sub-item) | AD14: NEW (repo sweep) | AE14: 2026-10-21 | AF14: INT-T-003 (requirements/intake/2026-10-21-supervisor-meeting-2026-10-14-notes-and-transcript.md); mapping design/ledger/notes/MEETINGS-MAPPING-20261021.md checked line by line by FND-0035 and FND-0036; REGISTER section H | AH14: No | AJ14: repo: REGISTER / COMPARISON | AK14: COMPARISON section 4 | AL14: S05
A15: C-D03/CONTEXT | B15: What do 'context' and 'scenario' mean (the request, the trajectory so far, the deployment)? | C15: PARTLY ANSWERED | D15: =IFERROR(INDEX(Lists!$B$2:$B$14,MATCH(C15,Lists!$A$2:$A$14,0)),"?") | E15: =IF(COUNTIFS(Links!$B$2:$B$600,A15,Links!$E$2:$E$600,"Yes")>0,"REVISE","") | F15: =COUNTIFS(Links!$B$2:$B$600,A15,Links!$D$2:$D$600,"No",Links!$C$2:$C$600,"<>INFORMS") | G15: JOAA-DECISION | H15: K3 Policy form | I15: G2 Before the affected pilot/arm | J15: High | K15: 37 | L15: W1 Decide | M15: S07 | N15: Joaa | O15: Use both senses explicitly in the contract; ask only if a choice depends on it | P15: No | Q15: Decision | R15: Sub-item | S15: C-D03 | T15: REQ-O14-09 / brief Q2: 'based on the context and based on the scenario it will be different' are undefined; the excerpt may be prescriptive or a prediction. | U15: Open. 2026-10-21 (AUTH-018): two senses in his words: on 14 October context is the situation, who invokes the agent and in what role ('based on who is invoking ... you will change the tools', INT-T-003 L261); on 21 October context is what the model is given: tools, knowledge, memory, invocation settings, input and output modalities (INT-T-002 L176-L190). 'Scenario' is not defined separately. | V15: Joaa's answer recorded in his words. | Y15: Q-J09, Q-J25 | AB15: DEC | AC15: n/a (sub-item) | AD15: NEW (repo sweep) | AE15: 2026-10-21 | AF15: INT-T-003 (requirements/intake/2026-10-21-supervisor-meeting-2026-10-14-notes-and-transcript.md); INT-T-002 (requirements/intake/2026-10-21-supervisor-meeting-2026-10-21-notes-and-transcript.md); mapping design/ledger/notes/MEETINGS-MAPPING-20261021.md checked line by line by FND-0035 and FND-0036; REGISTER section H | AH15: No | AJ15: repo: REGISTER / COMPARISON | AK15: REQ-O14-09, v4-01 Q2 | AL15: S05
A16: C-R02/C10-13 | B16: Offline/runtime label, D-node presentation, G vs C-A, A1-A5 disagreements | C16: PARTLY ANSWERED | D16: =IFERROR(INDEX(Lists!$B$2:$B$14,MATCH(C16,Lists!$A$2:$A$14,0)),"?") | E16: =IF(COUNTIFS(Links!$B$2:$B$600,A16,Links!$E$2:$E$600,"Yes")>0,"REVISE","") | F16: =COUNTIFS(Links!$B$2:$B$600,A16,Links!$D$2:$D$600,"No",Links!$C$2:$C$600,"<>INFORMS") | G16: RECORDS-AT-HAND | H16: K17 Record repair & procedure error | I16: G5 Housekeeping / no block | J16: Low | K16: 39 | L16: W1 Decide | M16: S07 | N16: You (presentation); team (E6) | O16: Lead drafts the fix; you approve | P16: Partly | Q16: Disagreement | R16: Sub-item | S16: C-R02 | T16: SRC-06 C10-C13 (grouped in SRC-11 D4): label accepted as accurate; D-node presentation is the user's decision; G vs C-A has no winner and selection inflation is unmeasured; A1-A5 disagreements persist; A6 withdrawn in v3. | U16: Presentation decided by the lead (AUTH-010); retained disagreements listed in v2-06 and v3-04. | V16: Independent re-check and a dated fix. | Y16: Q-U10 | AB16: RECORD+DATA | AC16: n/a (sub-item) | AD16: NEW (SRC-11 sub-row) | AE16: 2026-10-19 | AF16: WD-019/020; v2-06 section A; v3-04 section 3 | AH16: No for presentation | AJ16: SRC-11 section D4 | AK16: SRC-06 C10-C13, v2-06 A1-A5 | AL16: S05
